<?xml version="1.0"?>
<robot name="myrobot">
    <!-- Link descriptions -->
    <material name="blue">
        <color rgba="0 0 0.8 1"/>
    </material>

    <material name="black">
        <color rgba="0 0 0 1"/>
    </material>

    <material name="white">
        <color rgba="1 1 1 1"/>
    </material>

    <link name="base_link">
        <visual>
              <origin rpy="0 0 0" xyz="0 0 0"/>
              <geometry>
                  <box size="0.24 0.10 0.01"/>
              </geometry>
              <material name="blue"/>
        </visual>
    </link>

    <link name="base_footprint">
        <visual>
            <origin xyz="0 0 0" rpy="0 0 0" />
            <geometry>
                <box size="0.05 0.05 0.001" />
            </geometry>
            <material name="TransparentGreen" />
        </visual>
    </link>

    <link name="right_wheel_link">
        <visual>
            <origin rpy="1.57075 0 0" xyz="0 -0.05 0"/>
            <geometry>
                <cylinder length="0.025" radius="0.03"/>
            </geometry>
            <material name="black"/>
            <origin rpy="0 0 0" xyz="0 0 0"/>
        </visual>
    </link>

    <link name="left_wheel_link">
        <visual>
            <origin rpy="1.57075 0 0" xyz="0 0.05 0"/>
            <geometry>
                <cylinder length="0.025" radius="0.03"/>
            </geometry>
            <material name="black"/>
        </visual>
    </link>

    <link name="camera_link">
        <visual>
            <origin rpy="0 0 0" xyz="0.12 0 0.03"/>
            <geometry>
                <box size="0.005 0.04 0.07"/>
            </geometry>
            <material name="blue"/>
        </visual>
    </link>

    <!-- Joint descriptions -->
    <joint name="left_wheel" type="continuous">
	    <parent link="base_link"/>
	    <child link="left_wheel_link"/>
	    <axis xyz="0 1 0"/>
    </joint>

    <joint name="right_wheel" type="continuous">
    	<parent link="base_link"/>
        <child link="right_wheel_link"/>
        <axis xyz="0 1 0"/>
    </joint>

    <joint name="servo" type="revolute">
        <axis xyz="0 0 1"/>
        <limit effort="1000.0" lower="-0.12" upper="0.12" velocity="0.5"/>
    	<parent link="base_link"/>
	    <child link="camera_link"/>
    </joint>

    <!-- Joint to create a static transformation between the ground and the robot body -->
    <joint name="base_joint" type="fixed">
        <origin xyz="0 0 0.03" rpy="0 0 0" />
        <parent link="base_footprint"/>
        <child link="base_link" />
    </joint>
</robot>
